Workbook

Sheet 工作表1
A1: 202603半成品成本表:
A2: 項目 | B2: 材料名稱 | C2: 數量 | E2: 價格 | F2: 平均售價 | H2: 供應商 | I2: 備註
A4: 1 | B4: 黑胡椒醬+調粉 | C4: =[1]半成品配方!H12 -> 59 | D4: 份 | E4: =[1]半成品配方!G14+([1]半成品配方!H12*[1]半成品配方!G25)+(C4*[1]半成品配方!G59) -> 184.49205 | F4: =E4/C4 -> 3.1269838 | G4: 元/份 | H4: 青沄 | I4: 調粉(一般+香蒜粉)
A5: =A4+1 -> 2 | B5: 醬油膏 | C5: 1750 | D5: g | E5: =[1]半成品配方!G33 -> 41.579258 | F5: =E5/C5 -> 0.023759576 | G5: 元/g | H5: 青沄 | I5: 4.5罐塑膠瓶
A6: =A5+1 -> 3 | B6: 青醬包+調味品 | C6: =[1]半成品配方!B48 -> 22 | D6: 份 | E6: =[1]半成品配方!G47+([1]半成品配方!B48*[1]半成品配方!G59) -> 141.30138 | F6: =E6/C6 -> 6.4227899 | G6: 元/份 | H6: 青沄
A7: =A6+1 -> 4 | B7: 紅醬包+調味品 | C7: =[1]半成品配方!B79 -> 22 | D7: 份 | E7: =[1]半成品配方!G78+([1]半成品配方!B79*[1]半成品配方!G93)+([1]半成品配方!B79*[1]半成品配方!G91) -> 196.57614 | F7: =E7/C7 -> 8.935279 | G7: 元/份 | H7: 青沄
A8: =A7+1 -> 5 | B8: 白醬包+調味品 | C8: =[1]半成品配方!B158 -> 30 | D8: 份 | E8: =[1]半成品配方!G157+(30*[1]半成品配方!G175) -> 196.60389 | F8: =E8/C8 -> 6.5534631 | G8: 元/份 | H8: 青沄
A9: =A8+1 -> 6 | B9: 義大利麵 | C9: =[1]半成品配方!C103 -> 30 | D9: 份 | E9: =[1]半成品配方!G103 -> 164.09088 | F9: =E9/C9 -> 5.4696959 | G9: 元/份 | I9: 175g/份
A10: =A9+1 -> 7 | B10: 有機黎麥飯 | C10: =[1]半成品配方!C115 -> 14 | D10: 份 | E10: =[1]半成品配方!G114 -> 74.442367 | F10: =E10/C10 -> 5.3173119 | G10: 元/份 | H10: 青沄 | I10: 175g/份
A11: =A10+1 -> 8 | B11: 花蛤調味品 | C11: 120 | D11: g | E11: =[1]半成品配方!G122 -> 6.94 | F11: =E11/C11 -> 0.057833333 | G11: g/份 | H11: 青沄 | I11: 1平匙=2g/碗(1/2平匙)
A12: =A11+1 -> 9 | B12: 鹽水 | C12: =[1]半成品配方!C130 -> 370 | D12: g | E12: =[1]半成品配方!G130 -> 1.1566667 | F12: =E12/C12 -> 0.0031261261 | G12: g/份 | I12: 20g調味品+350g過濾水
A13: =A12+1 -> 10 | B13: 番茄沙拉醬 | C13: =[1]半成品配方!D205 -> 10 | D13: 份 | E13: =[1]半成品配方!G204 -> 4.3129032 | F13: =E13/C13 -> 0.43129032 | G13: g/份
A14: =A13+1 -> 11 | B14: 清檸合風醬 | C14: =[1]半成品配方!D214 -> 10 | D14: 份 | E14: =[1]半成品配方!G213 -> 6.1405897 | F14: =E14/C14 -> 0.61405897 | G14: 元/份
A15: =A14+1 -> 12 | B15: 高麗菜罐 | C15: 1 | D15: 份 | E15: ='[1]食,耗,包材成本'!K63 -> 2.1505376 | F15: =E15/C15 -> 2.1505376 | G15: 元/份
A16: =A15+1 -> 13 | B16: 脆薯 | C16: =[1]半成品配方!C234 -> 17 | D16: 份 | E16: =[1]半成品配方!G234 -> 201.6 | F16: =E16/C16 -> 11.858824 | G16: 元/份
A17: =A16+1 -> 14 | B17: 鮪魚玉米 | C17: =[1]半成品配方!C248 -> 20 | D17: 份 | E17: =[1]半成品配方!G246 -> 138.83 | F17: =E17/C17 -> 6.9415 | G17: 元/份
A18: =A17+1 -> 15 | B18: 花生香油醬 | C18: 110 | D18: g | E18: =[1]半成品配方!G254 -> 26.731376 | F18: =E18/C18 -> 0.24301251 | G18: 元/g
A19: =A18+1 -> 16 | B19: 雞條 | C19: =[1]半成品配方!C192 -> 76 | D19: 份 | E19: =[1]半成品配方!G190+(3*[1]半成品配方!G198) -> 749.62716 | F19: =E19/C19 -> 9.8635153 | G19: 元/份
A20: =A19+1 -> 17 | B20: 梅花豬片 | C20: =[1]半成品配方!C261 -> 25 | D20: 份 | E20: =[1]半成品配方!G259 -> 223 | F20: =E20/C20 -> 8.92 | G20: 元/份
A21: =A20+1 -> 18 | B21: 草原牛 | C21: =[1]半成品配方!C267 -> 30 | D21: 份 | E21: =[1]半成品配方!G265 -> 380 | F21: =E21/C21 -> 12.666667 | G21: 元/份
A22: =A21+1 -> 19 | B22: 百香果汁 | C22: =[1]半成品配方!C274 -> 16 | D22: 份 | E22: =[1]半成品配方!G273 -> 175.6 | F22: =E22/C22 -> 10.975 | G22: 元/份
A23: =A22+1 -> 20 | B23: 檸檬汁 | C23: =[1]半成品配方!C281 -> 38 | D23: 份 | E23: =[1]半成品配方!G280 -> 155.8 | F23: =E23/C23 -> 4.1 | G23: 元/份
A24: =A23+1 -> 21 | B24: 牛肋條醬+調粉 | C24: =[1]半成品配方!B298 -> 17 | D24: 份 | E24: =[1]半成品配方!G297+([1]半成品配方!E310*[1]半成品配方!B298) -> 413.67207 | F24: =E24/C24 -> 24.333651 | G24: 元/份
A25: =A24+1 -> 22 | B25: 梅花豬醬+調粉 | C25: =[1]半成品配方!B324 -> 15 | D25: 份 | E25: =[1]半成品配方!G323+([1]半成品配方!B324*[1]半成品配方!E335) -> 274.84505 | F25: =E25/C25 -> 18.323003 | G25: 元/份
A26: =A25+1 -> 23 | B26: 冬瓜飲 | C26: =[1]飲品配方與利潤!C201 -> 20 | D26: 份 | E26: =[1]飲品配方與利潤!G200 -> 63.573333 | F26: =E26/C26 -> 3.1786667 | G26: 元/份
A27: =A26+1 -> 24 | B27: 洛神花乾 | C27: =600/5 -> 120 | D27: 份 | E27: ='[1]食,耗,包材成本'!G10 -> 250 | F27: =E27/C27 -> 2.0833333 | G27: 元/份
A28: =A27+1 -> 25 | B28: 花蛤包 | C28: 6 | D28: 份 | E28: =F28*C28 -> 49.636364 | F28: =[1]半成品配方!E340 -> 8.2727273 | G28: 元/份
A29: =A28+1 -> 26 | B29: 地瓜 | C29: 20 | D29: 份 | E29: ='[1]食,耗,包材成本'!G28 -> 110 | F29: =E29/C29 -> 5.5 | G29: 元/份
A30: =A29+1 -> 27 | B30: 醬燒雞腿 | C30: =[1]半成品配方!B351 -> 20 | D30: 份 | E30: =[1]半成品配方!G350 -> 266.03248 | F30: =E30/C30 -> 13.301624 | G30: 元/份
A31: =A30+1 -> 28 | B31: 菇菇 | C31: =3000/50 -> 60 | D31: 份 | E31: ='[1]食,耗,包材成本'!G75 -> 150 | F31: =E31/C31 -> 2.5 | G31: 元/份
A32: =A31+1 -> 29 | B32: 雞條調味粉 | C32: =[1]半成品配方!C366 -> 180 | D32: g | E32: =[1]半成品配方!G366 -> 39 | F32: =E32/C32 -> 0.21666667 | G32: 元/g
A33: =A32+1 -> 30 | B33: 油炸物(吸+耗油) | C33: 80 | D33: g | E33: ='[1]食,耗,包材成本'!K41 -> 0.051094891 | F33: =C33*E33 -> 4.0875912 | G33: 元/g
A34: =A33+1 -> 31 | B34: 肉醬包 | C34: =[1]半成品配方!G140 -> 38 | D34: 包 | E34: =[1]半成品配方!G139 -> 289.03991 | F34: =E34/C34 -> 7.6063134 | G34: 元/份
A35: =A34+1 -> 32 | B35: 松子粒 | C35: ='[1]食,耗,包材成本'!C21/6 -> 100 | D35: 份 | E35: ='[1]食,耗,包材成本'!G21 -> 720 | F35: =E35/C35 -> 7.2 | G35: 元/份
A36: =A35+1 -> 33 | B36: 起司片 | C36: ='[1]食,耗,包材成本'!C31 -> 84 | D36: 片 | E36: ='[1]食,耗,包材成本'!G31 -> 310 | F36: =E36/C36 -> 3.6904762 | G36: 元/份
A37: =A36+1 -> 34 | B37: 蛋餅皮 | C37: ='[1]食,耗,包材成本'!E35/2 -> 15 | D37: 份 | E37: ='[1]食,耗,包材成本'!G35 -> 65 | F37: =E37/C37 -> 4.3333333 | G37: 元/份 | I37: 1份=2片
A38: =A37+1 -> 35 | B38: 薯餅 | C38: 20 | D38: 片 | E38: ='[1]食,耗,包材成本'!G33 -> 125 | F38: =E38/C38 -> 6.25 | G38: 元/片
A39: =A38+1 -> 36 | B39: 蘿蔔糕 | C39: ='[1]食,耗,包材成本'!C30/2 -> 5 | D39: 份 | E39: ='[1]食,耗,包材成本'!G30 -> 60 | F39: =E39/C39 -> 12 | G39: 元/份 | I39: 1份=2片
A40: =A39+1 -> 37 | B40: 吐司 | C40: ='[1]食,耗,包材成本'!C4/3 -> 8 | D40: 份 | E40: ='[1]食,耗,包材成本'!G4 -> 38 | F40: =E40/C40 -> 4.75 | G40: 元/份 | I40: 1份=3片
A41: =A40+1 -> 38 | B41: 雞胸 | C41: 1 | D41: 片 | E41: ='[1]食,耗,包材成本'!K51 -> 35.98 | F41: =E41/C41 -> 35.98 | G41: 元/份
...
